<?xml version="1.0" encoding="utf-8"?>
<!-- This URDF was automatically created by SolidWorks to URDF Exporter! Originally created by Stephen Brawner (brawner@gmail.com) 
     Commit Version: 1.5.1-0-g916b5db  Build Version: 1.5.7152.31018
     For more information, please see http://wiki.ros.org/sw_urdf_exporter -->
<robot
  name="DARS_right_arm" xmlns:xacro="http://www.ros.org/wiki/xacro">
  <link
    name="base_link">
    <inertial>
      <origin
        xyz="0.000286922689223201 -0.000193783025430286 0.061268550604531"
        rpy="0 0 0" />
      <mass
        value="1.12130208690655" />
      <inertia
        ixx="0.00286879446148421"
        ixy="4.16972264191551E-05"
        ixz="9.95025487701487E-06"
        iyy="0.00293845708504973"
        iyz="-1.77292246133471E-05"
        izz="0.00302949300291022" />
    </inertial>
    <visual>
      <origin
        xyz="0 0 0"
        rpy="0 0 0" />
      <geometry>
        <mesh
          filename="package://DARS_right_arm/meshes/base_link.STL" />
      </geometry>
      <material
        name="">
        <color
          rgba="0.792156862745098 0.819607843137255 0.933333333333333 1" />
      </material>
    </visual>
    <collision>
      <origin
        xyz="0 0 0"
        rpy="0 0 0" />
      <geometry>
        <mesh
          filename="package://DARS_right_arm/meshes/base_link.STL" />
      </geometry>
    </collision>
  </link>
  <link
    name="right_arm_link1">
    <inertial>
      <origin
        xyz="-0.019386 0.022015 -0.0014203"
        rpy="0 0 0" />
      <mass
        value="0.70473" />
      <inertia
        ixx="0.0014492"
        ixy="-0.00024227"
        ixz="3.5667E-05"
        iyy="0.00084125"
        iyz="3.1392E-05"
        izz="0.0013026" />
    </inertial>
    <visual>
      <origin
        xyz="0 0 0"
        rpy="0 0 0" />
      <geometry>
        <mesh
          filename="package://DARS_right_arm/meshes/right_arm_link1.STL" />
      </geometry>
      <material
        name="">
        <color
          rgba="0.79216 0.81961 0.93333 1" />
      </material>
    </visual>
    <collision>
      <origin
        xyz="0 0 0"
        rpy="0 0 0" />
      <geometry>
        <mesh
          filename="package://DARS_right_arm/meshes/right_arm_link1.STL" />
      </geometry>
    </collision>
  </link>
  <joint
    name="right_arm_joint1"
    type="revolute">
    <origin
      xyz="5.4262E-05 0.00022204 0.206"
      rpy="-1.5708 0 -1.57" />
    <parent
      link="base_link" />
    <child
      link="right_arm_link1" />
    <axis
      xyz="0 -1 0" />

    <limit lower="-${6.2832*0.5}" upper="${6.2832*0.5}" effort="10" velocity="0.791943" />
  </joint>
  <link
    name="right_arm_link2">
    <inertial>
      <origin
        xyz="-0.0101764547557658 0.0683779127650883 -0.000745580998248896"
        rpy="0 0 0" />
      <mass
        value="1.34252498565416" />
      <inertia
        ixx="0.00538329600220053"
        ixy="-0.000875688876901923"
        ixz="2.64484051171643E-05"
        iyy="0.00182396730654474"
        iyz="-1.50157955683347E-05"
        izz="0.00536182675727726" />
    </inertial>
    <visual>
      <origin
        xyz="0 0 0"
        rpy="0 0 0" />
      <geometry>
        <mesh
          filename="package://DARS_right_arm/meshes/right_arm_link2.STL" />
      </geometry>
      <material
        name="">
        <color
          rgba="0.792156862745098 0.819607843137255 0.933333333333333 1" />
      </material>
    </visual>
    <collision>
      <origin
        xyz="0 0 0"
        rpy="0 0 0" />
      <geometry>
        <mesh
          filename="package://DARS_right_arm/meshes/right_arm_link2.STL" />
      </geometry>
    </collision>
  </link>
  <joint
    name="right_arm_joint2"
    type="revolute">
    <origin
      xyz="0 0 0"
      rpy="0 0 -3.1416" />
    <parent
      link="right_arm_link1" />
    <child
      link="right_arm_link2" />
    <axis
      xyz="1 0 0" />

    <limit lower="-${6.2832*0.125}" upper="${6.2832*0.25}" effort="10" velocity="0.791943" />
  </joint>
  <link
    name="right_arm_link3">
    <inertial>
      <origin
        xyz="-0.0352526033444867 0.000317620105370953 -0.0047077145274422"
        rpy="0 0 0" />
      <mass
        value="1.07736180137224" />
      <inertia
        ixx="0.00117795652515341"
        ixy="-1.84277786522819E-05"
        ixz="0.000469868838578303"
        iyy="0.00458889626091873"
        iyz="-5.93123698985668E-06"
        izz="0.00456075704021931" />
    </inertial>
    <visual>
      <origin
        xyz="0 0 0"
        rpy="0 0 0" />
      <geometry>
        <mesh
          filename="package://DARS_right_arm/meshes/right_arm_link3.STL" />
      </geometry>
      <material
        name="">
        <color
          rgba="0.792156862745098 0.819607843137255 0.933333333333333 1" />
      </material>
    </visual>
    <collision>
      <origin
        xyz="0 0 0"
        rpy="0 0 0" />
      <geometry>
        <mesh
          filename="package://DARS_right_arm/meshes/right_arm_link3.STL" />
      </geometry>
    </collision>
  </link>
  <joint
    name="right_arm_joint3"
    type="revolute">
    <origin
      xyz="0 0.289 0"
      rpy="-1.5708 0 1.5708" />
    <parent
      link="right_arm_link2" />
    <child
      link="right_arm_link3" />
    <axis
      xyz="1 0 0" />
      
    <limit lower="-${6.2832*0.5}" upper="${6.2832*0.5}" effort="10" velocity="1.2671" />
  </joint>
  <link
    name="right_arm_link4">
    <inertial>
      <origin
        xyz="-0.00838965435821876 0.0525508064837414 -0.000565913869525259"
        rpy="0 0 0" />
      <mass
        value="0.604541191485651" />
      <inertia
        ixx="0.00146411042879646"
        ixy="-0.000248216087152858"
        ixz="7.15930474693799E-06"
        iyy="0.000479638206681757"
        iyz="-3.48004015916206E-06"
        izz="0.00146664455964936" />
    </inertial>
    <visual>
      <origin
        xyz="0 0 0"
        rpy="0 0 0" />
      <geometry>
        <mesh
          filename="package://DARS_right_arm/meshes/right_arm_link4.STL" />
      </geometry>
      <material
        name="">
        <color
          rgba="0.792156862745098 0.819607843137255 0.933333333333333 1" />
      </material>
    </visual>
    <collision>
      <origin
        xyz="0 0 0"
        rpy="0 0 0" />
      <geometry>
        <mesh
          filename="package://DARS_right_arm/meshes/right_arm_link4.STL" />
      </geometry>
    </collision>
  </link>
  <joint
    name="right_arm_joint4"
    type="revolute">
    <origin
      xyz="0.061 0 0"
      rpy="1.5708 1.5708 0" />
    <parent
      link="right_arm_link3" />
    <child
      link="right_arm_link4" />
    <axis
      xyz="1 0 0" />

    <limit lower="-${6.2832*0.125}" upper="${6.2832*0.25}" effort="10" velocity="1.5708" />
  </joint>
  <link
    name="right_arm_link5">
    <inertial>
      <origin
        xyz="-0.080781942643494 -0.00378005644415225 0.000274844650583805"
        rpy="0 0 0" />
      <mass
        value="0.583482841125638" />
      <inertia
        ixx="0.000460079584835922"
        ixy="-0.00020596127667892"
        ixz="-1.03103186963589E-05"
        iyy="0.00219361107570785"
        iyz="-4.40507639217703E-06"
        izz="0.00220499653071847" />
    </inertial>
    <visual>
      <origin
        xyz="0 0 0"
        rpy="0 0 0" />
      <geometry>
        <mesh
          filename="package://DARS_right_arm/meshes/right_arm_link5.STL" />
      </geometry>
      <material
        name="">
        <color
          rgba="0.792156862745098 0.819607843137255 0.933333333333333 1" />
      </material>
    </visual>
    <collision>
      <origin
        xyz="0 0 0"
        rpy="0 0 0" />
      <geometry>
        <mesh
          filename="package://DARS_right_arm/meshes/right_arm_link5.STL" />
      </geometry>
    </collision>
  </link>
  <joint
    name="right_arm_joint5"
    type="revolute">
    <origin
      xyz="0 0.112 0"
      rpy="3.033 0 -1.5708" />
    <parent
      link="right_arm_link4" />
    <child
      link="right_arm_link5" />
    <axis
      xyz="-1 0 0" />

    <limit lower="-${6.2832*0.5}" upper="${6.2832*0.5}" effort="10" velocity="1.5708" />
  </joint>
  <link
    name="right_arm_link6">
    <inertial>
      <origin
        xyz="-0.0133305992280831 0.012880144801466 -0.00081879111278782"
        rpy="0 0 0" />
      <mass
        value="0.1753680671742" />
      <inertia
        ixx="0.00013773172240138"
        ixy="-2.38343394121477E-05"
        ixz="3.3303864281338E-06"
        iyy="8.18768876543453E-05"
        iyz="2.97467577143616E-06"
        izz="0.000125900406006971" />
    </inertial>
    <visual>
      <origin
        xyz="0 0 0"
        rpy="0 0 0" />
      <geometry>
        <mesh
          filename="package://DARS_right_arm/meshes/right_arm_link6.STL" />
      </geometry>
      <material
        name="">
        <color
          rgba="0.792156862745098 0.819607843137255 0.933333333333333 1" />
      </material>
    </visual>
    <collision>
      <origin
        xyz="0 0 0"
        rpy="0 0 0" />
      <geometry>
        <mesh
          filename="package://DARS_right_arm/meshes/right_arm_link6.STL" />
      </geometry>
    </collision>
  </link>
  <joint
    name="right_arm_joint6"
    type="revolute">
    <origin
      xyz="-0.1725 -0.00099411 -0.00010834"
      rpy="3.1416 0.10856 -1.5708" />
    <parent
      link="right_arm_link5" />
    <child
      link="right_arm_link6" />
    <axis
      xyz="1 0 0" />

    <limit lower="-${6.2832*0.125}" upper="${6.2832*0.25}" effort="10" velocity="1.5708" />
  </joint>
  <link
    name="right_arm_link7">
    <inertial>
      <origin
        xyz="7.63078008575446E-06 0.020478995776156 -2.93004968121569E-05"
        rpy="0 0 0" />
      <mass
        value="0.196442009012192" />
      <inertia
        ixx="0.000119683219838743"
        ixy="-3.48297706217317E-08"
        ixz="-3.60498623522632E-07"
        iyy="9.65519757763088E-05"
        iyz="1.33856853074309E-07"
        izz="0.000120752802255629" />
    </inertial>
    <visual>
      <origin
        xyz="0 0 0"
        rpy="0 0 0" />
      <geometry>
        <mesh
          filename="package://DARS_right_arm/meshes/right_arm_link7.STL" />
      </geometry>
      <material
        name="">
        <color
          rgba="0.792156862745098 0.819607843137255 0.933333333333333 1" />
      </material>
    </visual>
    <collision>
      <origin
        xyz="0 0 0"
        rpy="0 0 0" />
      <geometry>
        <mesh
          filename="package://DARS_right_arm/meshes/right_arm_link7.STL" />
      </geometry>
    </collision>
  </link>
  <joint
    name="right_arm_joint7"
    type="revolute">
    <origin
      xyz="0 0.0995 0"
      rpy="3.1416 -0.38529 0" />
    <parent
      link="right_arm_link6" />
    <child
      link="right_arm_link7" />
    <axis
      xyz="0 -1 0" />

    <limit lower="-${6.2832*1}" upper="${6.2832*1}" effort="10" velocity="1.5708" />
  </joint>
</robot>