<?xml version="1.0" ?>
<robot xmlns:xacro="http://ros.org/wiki/xacro">
<!-- xacro:include filename="$(find itri_resources)/urdf/common_materials.xacro"/ -->

<xacro:macro name="itri_ar607" params="prefix">
  <!-- meshes: main serial chain -->
  <link name="${prefix}base_link">
    <inertial>
      <mass value="9.522365"/>
      <inertia ixx="0.144495" ixy="-9e-06" ixz="-0.03076" iyy="0.183352" iyz="-3.7e-05" izz="0.079873"/>
    </inertial>
    <collision name="${prefix}base_link">
      <origin rpy="0  0  0" xyz="0    0    0.25"/>
      <geometry>
        <mesh filename="package://itri_support/meshes/ar607/collision/base.dae" scale="1.0 1.0 1.0"/>
      </geometry>
    </collision>
    <visual name="${prefix}base_link">
      <origin rpy="0  0  0" xyz="0    0    0.25"/>
      <geometry>
        <mesh filename="package://itri_support/meshes/ar607/visual/base.stl" scale="1.0 1.0 1.0"/>
      </geometry>
    </visual>
  </link>
  <link name="${prefix}link1">
    <inertial>
      <mass value="5.61696"/>
      <inertia ixx="0.087433" ixy="0.0" ixz="0.013287" iyy="0.073064" iyz="1.9e-05" izz="0.039829"/>
    </inertial>
    <collision name="${prefix}link1">
      <origin rpy="0  0  0" xyz="0     0.075  0.345"/>
      <geometry>
        <mesh filename="package://itri_support/meshes/ar607/collision/link1.dae" scale="1.0 1.0 1.0"/>
      </geometry>
    </collision>
    <visual name="${prefix}link1">
      <origin rpy="0  0  0" xyz="0     0.075  0.345"/>
      <geometry>
        <mesh filename="package://itri_support/meshes/ar607/visual/link1.stl" scale="1.0 1.0 1.0"/>
      </geometry>
    </visual>
  </link>
  <link name="${prefix}link2">
    <inertial>
      <mass value="7.350069"/>
      <inertia ixx="0.299465" ixy="-1e-05" ixz="-0.012735" iyy="0.279554" iyz="5.3e-05" izz="0.035911"/>
    </inertial>
    <collision name="${prefix}link2">
      <origin rpy="0  0  0" xyz="0    0    0.27"/>
      <geometry>
        <mesh filename="package://itri_support/meshes/ar607/collision/link2.dae" scale="1.0 1.0 1.0"/>
      </geometry>
    </collision>
    <visual name="${prefix}link2">
      <origin rpy="0  0  0" xyz="0    0    0.27"/>
      <geometry>
        <mesh filename="package://itri_support/meshes/ar607/visual/link2.stl" scale="1.0 1.0 1.0"/>
      </geometry>
    </visual>
  </link>
  <link name="${prefix}link3">
    <inertial>
      <mass value="3.724767"/>
      <inertia ixx="0.011733" ixy="4.3e-05" ixz="0.000461" iyy="0.019531" iyz="2.4e-05" izz="0.014154"/>
    </inertial>
    <collision name="${prefix}link3">
      <origin rpy="0  0  0" xyz="0     0.106  0.09"/>
      <geometry>
        <mesh filename="package://itri_support/meshes/ar607/collision/link3.dae" scale="1.0 1.0 1.0"/>
      </geometry>
    </collision>
    <visual name="${prefix}link3">
      <origin rpy="0  0  0" xyz="0     0.106  0.09"/>
      <geometry>
        <mesh filename="package://itri_support/meshes/ar607/visual/link3.stl" scale="1.0 1.0 1.0"/>
      </geometry>
    </visual>
  </link>
  <link name="${prefix}link4">
    <inertial>
      <mass value="3.245188"/>
      <inertia ixx="0.007141" ixy="0.000562" ixz="0.000255" iyy="0.054197" iyz="2.4e-05" izz="0.056111"/>
    </inertial>
    <collision name="${prefix}link4">
      <origin rpy="0  0  0" xyz="0     0.295  0"/>
      <geometry>
        <mesh filename="package://itri_support/meshes/ar607/collision/link4.dae" scale="1.0 1.0 1.0"/>
      </geometry>
    </collision>
    <visual name="${prefix}link4">
      <origin rpy="0  0  0" xyz="0     0.295  0"/>
      <geometry>
        <mesh filename="package://itri_support/meshes/ar607/visual/link4.stl" scale="1.0 1.0 1.0"/>
      </geometry>
    </visual>
  </link>
  <link name="${prefix}link5">
    <inertial>
      <mass value="0.501938"/>
      <inertia ixx="0.000539" ixy="1e-06" ixz="0.0" iyy="0.000892" iyz="-1e-06" izz="0.000962"/>
    </inertial>
    <collision name="${prefix}link5">
      <origin rpy="0  0  0" xyz="0  0  0"/>
      <geometry>
        <mesh filename="package://itri_support/meshes/ar607/collision/link5.dae" scale="1.0 1.0 1.0"/>
      </geometry>
    </collision>
    <visual name="${prefix}link5">
      <origin rpy="0  0  0" xyz="0  0  0"/>
      <geometry>
        <mesh filename="package://itri_support/meshes/ar607/visual/link5.stl" scale="1.0 1.0 1.0"/>
      </geometry>
    </visual>
  </link>
  <link name="${prefix}link6">
    <inertial>
      <mass value="0.038575"/>
      <inertia ixx="0.0005" ixy="0.0" ixz="0.0" iyy="0.0005" iyz="0.0" izz="0.0005"/>
    </inertial>
    <collision name="${prefix}link6">
      <origin rpy="1.57079  0  0" xyz="0     0     0.102"/>
      <geometry>
        <mesh filename="package://itri_support/meshes/ar607/collision/link6.dae" scale="1.0 1.0 1.0"/>
      </geometry>
    </collision>
    <visual name="${prefix}link6">
      <origin rpy="0  0  0" xyz="0     0     0.102"/>
      <geometry>
        <mesh filename="package://itri_support/meshes/ar607/visual/link6.stl" scale="1.0 1.0 1.0"/>
      </geometry>
    </visual>
  </link>
  <!-- end of link list -->
  
  <!-- joints: main serial chain -->
  <joint name="${prefix}joint1" type="revolute">
    <parent link="${prefix}base_link"/>
    <child link="${prefix}link1"/>
    <origin rpy="0  0  0" xyz="0  0  0"/>
    <axis xyz="0  0  1"/>
    <dynamics damping="0.7" friction="0.7"/>
    <limit effort="30.0" lower="-2.9657" upper="2.9657" velocity="3.45575"/>
  </joint>
  <joint name="${prefix}joint2" type="revolute">
    <parent link="${prefix}link1"/>
    <child link="${prefix}link2"/>
    <origin rpy="0  0  0" xyz="0     0.075  0.345"/>
    <axis xyz="1  0  0"/>
    <dynamics damping="0.7" friction="0.7"/>
    <limit effort="30.0" lower="-1.466" upper="2.3562" velocity="3.87463"/>
  </joint>
  <joint name="${prefix}joint3" type="revolute">
    <parent link="${prefix}link2"/>
    <child link="${prefix}link3"/>
    <origin rpy="0  0  0" xyz="0    0    0.27"/>
    <axis xyz="1  0  0"/>
    <dynamics damping="0.7" friction="0.7"/>
    <limit effort="30.0" lower="-1.3088" upper="1.7287" velocity="3.87463"/>
  </joint>
  <joint name="${prefix}joint4" type="revolute">
    <parent link="${prefix}link3"/>
    <child link="${prefix}link4"/>
    <origin rpy="0  0  0" xyz="0    0    0.09"/>
    <axis xyz="0  1  0"/>
    <dynamics damping="0.7" friction="0.7"/>
    <limit effort="30.0" lower="-3.3156" upper="3.3156" velocity="5.75958"/>
  </joint>
  <joint name="${prefix}joint5" type="revolute">
    <parent link="${prefix}link4"/>
    <child link="${prefix}link5"/>
    <origin rpy="0  0  0" xyz="0     0.295  0"/>
    <axis xyz="1  0  0"/>
    <dynamics damping="0.7" friction="0.7"/>
    <limit effort="30.0" lower="-2.0246" upper="2.0246" velocity="5.75958"/>
  </joint>
  <joint name="${prefix}joint6" type="revolute">
    <parent link="${prefix}link5"/>
    <child link="${prefix}link6"/>
    <origin rpy="0 -1.57079 -1.57079" xyz="0  0  0"/>
    <axis xyz="0  0  1"/>
    <dynamics damping="0.7" friction="0.7"/>
    <limit effort="30.0" lower="-6.28" upper="6.28" velocity="5.75958"/>
  </joint>
  <!-- end of joint list -->

  <!-- ROS-Industrial 'flange' frame: attachment point for EEF models -->
  <link name="${prefix}flange" />
  <joint name="${prefix}joint_6-flange" type="fixed">
    <origin xyz="0 0 0.10" rpy="0 0 0" />
    <parent link="${prefix}link6" />
    <child link="${prefix}flange" />
  </joint>

</xacro:macro>
</robot>
