<?xml version="1.0" encoding="utf-8"?>
<robot xmlns:xacro="http://ros.org/wiki/xacro">
  <!-- safety_distance: Minimum safety distance in [m] by which the collision volumes are expanded and which is enforced during robot motions -->
  <xacro:macro name="hand" params="prefix connected_to:='' rpy:='0 0 0' xyz:='0 0 0'">
    <link name="${prefix}hand">
      <inertial>
        <mass value="0.73" />
        <origin xyz="0 0.0015244 -0.09275912" rpy="0 0 0" />
        <inertia ixx="0.00278560230025" ixy="0.0" ixz="0.0" iyy="0.000400033405336" iyz="0.0" izz="0.00256378041832" />
      </inertial>
      <visual>
        <origin xyz="0 0 -0.09" rpy="0 0 0"/>
        <geometry>
          <mesh filename="package://itri_support/meshes/gripper/visual/hand.stl"/>
        </geometry>
      </visual>
      <collision>
        <origin xyz="0 0 -0.09" rpy="0 0 0"/>
        <geometry>
          <mesh filename="package://itri_support/meshes/gripper/collision/hand.stl"/>
        </geometry>
      </collision>
    </link>
    <!-- link name="leftfinger">
      <inertial>
        <mass value="0.1" />
        <origin xyz="0 0.0145644 0.0227941" rpy="0 0 0" />
        <inertia ixx="3.01220925051e-05" ixy="0.0" ixz="0.0" iyy="2.95873808038e-05" iyz="0.0" izz="6.95125211657e-06" />
      </inertial>
      <visual>
        <origin xyz="${xyz}" rpy="0 0 0"/>
        <geometry>
          <mesh filename="package://itri_support/meshes/gripper/visual/finger.dae"/>
        </geometry>
      </visual>
      <collision>
        <origin xyz="${xyz}" rpy="0 0 0"/>
        <geometry>
          <mesh filename="package://itri_support/meshes/gripper/collision/finger.stl"/>
        </geometry>
      </collision>
    </link>
    <link name="rightfinger">
      <inertial>
        <mass value="0.1" />
        <origin xyz="0 -0.0145644 0.0227941" rpy="0 0 ${pi}" />
        <inertia ixx="3.01220925051e-05" ixy="0.0" ixz="0.0" iyy="2.95873808038e-05" iyz="0.0" izz="6.95125211657e-06" />
      </inertial>
      <visual>
        <origin xyz="${xyz}" rpy="0 0 ${pi}"/>
        <geometry>
          <mesh filename="package://itri_support/meshes/gripper/visual/finger.dae"/>
        </geometry>
      </visual>
      <collision>
        <origin xyz="${xyz}" rpy="0 0 ${pi}"/>
        <geometry>
          <mesh filename="package://itri_support/meshes/gripper/collision/finger.stl"/>
        </geometry>
      </collision>
    </link -->
    <link name="${prefix}rightfinger">
      <inertial>
        <origin rpy="0 0 0" xyz="0.0 0 0" />
        <mass value="0.1" />
        <inertia ixx="0.002" ixy="0" ixz="0" iyy="0.002" iyz="0" izz="0.002" />
      </inertial>
      <visual>
        <origin rpy="0 0 0" xyz="0 0.11685 0" />
        <geometry>
          <mesh filename="package://itri_support/meshes/gripper/visual/r_gripper_finger_link.stl" />
        </geometry>
      </visual>
      <collision>
        <origin rpy="0 0 0" xyz="0 0.11685 0" />
        <geometry>
          <mesh filename="package://itri_support/meshes/gripper/collision/r_gripper_finger_link.stl" />
        </geometry>
      </collision>
    </link>
    <link name="${prefix}leftfinger">
      <inertial>
        <origin rpy="0 0 0" xyz="0.0 0 0" />
        <mass value="0.1" />
        <inertia ixx="0.002" ixy="0" ixz="0" iyy="0.002" iyz="0" izz="0.002" />
      </inertial>
      <visual>
        <origin rpy="0 0 0" xyz="0 -0.11685 0" />
        <geometry>
          <mesh filename="package://itri_support/meshes/gripper/visual/l_gripper_finger_link.stl" />
        </geometry>
      </visual>
      <collision>
        <origin rpy="0 0 0" xyz="0 -0.11685 0" />
        <geometry>
          <mesh filename="package://itri_support/meshes/gripper/collision/l_gripper_finger_link.stl" />
        </geometry>
      </collision>
    </link>

    <!-- joint name="${prefix}finger_joint1" type="prismatic">
      <parent link="${prefix}hand"/>
      <child link="${prefix}leftfinger"/>
      <origin xyz="0 0 0.0584" rpy="0 0 0"/>
      <axis xyz="0 1 0"/>
      <limit effort="20" lower="0.0" upper="0.05" velocity="0.05"/>
    </joint>
    <joint name="${prefix}finger_joint2" type="prismatic">
      <parent link="${prefix}hand"/>
      <child link="${prefix}rightfinger"/>
      <origin xyz="0 0 0.0584" rpy="0 0 0"/>
      <axis xyz="0 -1 0"/>
      <limit effort="20" lower="0.0" upper="0.05" velocity="0.05"/>
    </joint -->
    <joint name="${prefix}finger_joint1" type="prismatic">
      <origin rpy="0 ${-pi/2} 0" xyz="0 0 0" />
      <parent link="${prefix}hand" />
      <child link="${prefix}rightfinger" />
      <axis xyz="0 1 0" />
      <limit effort="60" lower="0.0" upper="0.05" velocity="0.05" />
    </joint>
    <joint name="${prefix}finger_joint2" type="prismatic">
      <origin rpy="0 ${-pi/2} 0" xyz="0 0 0" />
      <parent link="${prefix}hand" />
      <child link="${prefix}leftfinger" />
      <axis xyz="0 -1 0" />
      <limit effort="60" lower="0.0" upper="0.05" velocity="0.05" />
    </joint>

    <xacro:unless value="${connected_to == ''}">
      <joint name="${prefix}hand_joint" type="fixed">
        <parent link="${connected_to}"/>
        <child link="${prefix}hand"/>
        <origin xyz="${xyz}" rpy="${rpy}"/>
      </joint>
      <!-- gazebo reference="${prefix}hand_joint">
        <disableFixedJointLumping>true</disableFixedJointLumping>
      </gazebo -->
    </xacro:unless>

    <xacro:arg name="gazebo" default="true"/>
    <xacro:if value="$(arg gazebo)">
      <!-- Gazebo Tags -->
      <xacro:include filename="$(find itri_support)/urdf/ar607/hand_transmission.xacro"/>
      <xacro:hand_transmission prefix="${prefix}"/>
    </xacro:if>
    
  </xacro:macro>
</robot>